<?xml version="1.0" ?>
<robot name="hgrobot">

    <link name="base_link">
        <visual>
            <origin xyz="0 0 0" rpy="0 0 0"/>
            <geometry>
                <!-- <cylinder length="0.16" radius="0.20"/> -->
                <box size="0.5 0.4 0.15"/>
            </geometry>
            <material name="yellow">
                <color rgba="1 0.4 0 1"/>
            </material>
        </visual>
    </link>

    <joint name="left_wheel_joint" type="continuous">
        <origin xyz="0 0.19 -0.05" rpy="0 0 0"/>
        <parent link="base_link"/>
        <child link="left_wheel_link"/>
        <axis xyz="0 1 0"/>
    </joint>

    <link name="left_wheel_link">
        <visual>
            <origin xyz="0 0 0" rpy="1.5707 0 0" />
            <geometry>
                <cylinder radius="0.06" length = "0.025"/>
            </geometry>
            <material name="white">
                <color rgba="1 1 1 0.9"/>
            </material>
        </visual>
    </link>

    <joint name="right_wheel_joint" type="continuous">
        <origin xyz="0 -0.19 -0.05" rpy="0 0 0"/>
        <parent link="base_link"/>
        <child link="right_wheel_link"/>
        <axis xyz="0 1 0"/>
    </joint>

    <link name="right_wheel_link">
        <visual>
            <origin xyz="0 0 0" rpy="1.5707 0 0" />
            <geometry>
                <cylinder radius="0.06" length = "0.025"/>
            </geometry>
            <material name="white">
                <color rgba="1 1 1 0.9"/>
            </material>
        </visual>
    </link>

    <joint name="frontl_caster_joint" type="continuous">
        <origin xyz="0.18 0.10 -0.095" rpy="0 0 0"/>
        <parent link="base_link"/>
        <child link="frontl_caster_link"/>
        <axis xyz="0 1 0"/>
    </joint>

    <link name="frontl_caster_link">
        <visual>
            <origin xyz="0 0 0" rpy="0 0 0"/>
            <geometry>
                <sphere radius="0.015" />
            </geometry>
            <material name="black">
                <color rgba="0 0 0 0.95"/>
            </material>
        </visual>
    </link>

    <joint name="frontr_caster_joint" type="continuous">
        <origin xyz="0.18 -0.10 -0.095" rpy="0 0 0"/>
        <parent link="base_link"/>
        <child link="frontr_caster_link"/>
        <axis xyz="0 1 0"/>
    </joint>

    <link name="frontr_caster_link">
        <visual>
            <origin xyz="0 0 0" rpy="0 0 0"/>
            <geometry>
                <sphere radius="0.015" />
            </geometry>
            <material name="black">
                <color rgba="0 0 0 0.95"/>
            </material>
        </visual>
    </link>

    <joint name="backl_caster_joint" type="continuous">
        <origin xyz="-0.18 0.10 -0.095" rpy="0 0 0"/>
        <parent link="base_link"/>
        <child link="backl_caster_link"/>
        <axis xyz="0 1 0"/>
    </joint>

    <link name="backl_caster_link">
        <visual>
            <origin xyz="0 0 0" rpy="0 0 0"/>
            <geometry>
                <sphere radius="0.015" />
            </geometry>
            <material name="black">
                <color rgba="0 0 0 0.95"/>
            </material>
        </visual>
    </link>
    <joint name="backr_caster_joint" type="continuous">
        <origin xyz="-0.18 -0.10 -0.095" rpy="0 0 0"/>
        <parent link="base_link"/>
        <child link="backr_caster_link"/>
        <axis xyz="0 1 0"/>
    </joint>

    <link name="backr_caster_link">
        <visual>
            <origin xyz="0 0 0" rpy="0 0 0"/>
            <geometry>
                <sphere radius="0.015" />
            </geometry>
            <material name="black">
                <color rgba="0 0 0 0.95"/>
            </material>
        </visual>
    </link>

</robot>
